Workbook

Sheet Orders
A1: Order_ID | B1: Order_Date | C1: Customer_ID | D1: Product_ID | E1: Product_Name | F1: Category | G1: Region | H1: State | I1: City | J1: Sales_Channel | K1: Quantity | L1: Unit_Price | M1: Discount | N1: Cost | O1: Revenue | P1: Profit | Q1: Profit_Margin | R1: Month | S1: Year_Month
A2: O000447 | B2: 2025-01-01 | C2: C0522 | D2: P0016 | E2: Casual Shirt | F2: Fashion | G2: North | H2: Haryana | I2: Faridabad | J2: Store | K2: 3 | L2: 1311.58 | M2: 0.2 | N2: 2643.14 | O2: =K2*L2*(1-M2) | P2: =O2-N2 | Q2: =IFERROR(P2/O2,0) | R2: =TEXT(DATEVALUE(B2),"mmm") | S2: =TEXT(DATEVALUE(B2),"yyyy-mm")
A3: O004192 | B3: 2025-01-01 | C3: C0305 | D3: P0022 | E3: Face Wash | F3: Beauty | G3: North | H3: Delhi | I3: New Delhi | J3: Online | K3: 4 | L3: 554.13 | M3: 0.1 | N3: 1388.41 | O3: =K3*L3*(1-M3) | P3: =O3-N3 | Q3: =IFERROR(P3/O3,0) | R3: =TEXT(DATEVALUE(B3),"mmm") | S3: =TEXT(DATEVALUE(B3),"yyyy-mm")
A4: O003581 | B4: 2025-01-01 | C4: C0355 | D4: P0028 | E4: Trimmer | F4: Beauty | G4: West | H4: Maharashtra | I4: Thane | J4: Online | K4: 6 | L4: 441.36 | M4: 0.05 | N4: 1553.15 | O4: =K4*L4*(1-M4) | P4: =O4-N4 | Q4: =IFERROR(P4/O4,0) | R4: =TEXT(DATEVALUE(B4),"mmm") | S4: =TEXT(DATEVALUE(B4),"yyyy-mm")
A5: O003276 | B5: 2025-01-01 | C5: C0608 | D5: P0003 | E5: Smartwatch | F5: Electronics | G5: West | H5: Maharashtra | I5: Nagpur | J5: Store | K5: 2 | L5: 2309.18 | M5: 0.05 | N5: 2400.66 | O5: =K5*L5*(1-M5) | P5: =O5-N5 | Q5: =IFERROR(P5/O5,0) | R5: =TEXT(DATEVALUE(B5),"mmm") | S5: =TEXT(DATEVALUE(B5),"yyyy-mm")
A6: O003072 | B6: 2025-01-01 | C6: C0260 | D6: P0014 | E6: Coffee Maker | F6: Home & Kitchen | G6: South | H6: Tamil Nadu | I6: Chennai | J6: Store | K6: 4 | L6: 1001.34 | M6: 0 | N6: 3067.32 | O6: =K6*L6*(1-M6) | P6: =O6-N6 | Q6: =IFERROR(P6/O6,0) | R6: =TEXT(DATEVALUE(B6),"mmm") | S6: =TEXT(DATEVALUE(B6),"yyyy-mm")
A7: O002011 | B7: 2025-01-01 | C7: C0581 | D7: P0022 | E7: Face Wash | F7: Beauty | G7: North | H7: Haryana | I7: Faridabad | J7: Online | K7: 5 | L7: 537.06 | M7: 0.1 | N7: 1723.22 | O7: =K7*L7*(1-M7) | P7: =O7-N7 | Q7: =IFERROR(P7/O7,0) | R7: =TEXT(DATEVALUE(B7),"mmm") | S7: =TEXT(DATEVALUE(B7),"yyyy-mm")
A8: O001988 | B8: 2025-01-01 | C8: C0732 | D8: P0007 | E8: Wireless Mouse | F8: Electronics | G8: North | H8: Uttar Pradesh | I8: Varanasi | J8: Store | K8: 2 | L8: 1024.87 | M8: 0.1 | N8: 1273.97 | O8: =K8*L8*(1-M8) | P8: =O8-N8 | Q8: =IFERROR(P8/O8,0) | R8: =TEXT(DATEVALUE(B8),"mmm") | S8: =TEXT(DATEVALUE(B8),"yyyy-mm")
A9: O002071 | B9: 2025-01-01 | C9: C0667 | D9: P0007 | E9: Wireless Mouse | F9: Electronics | G9: West | H9: Goa | I9: Panaji | J9: Online | K9: 1 | L9: 952.68 | M9: 0.05 | N9: 601.74 | O9: =K9*L9*(1-M9) | P9: =O9-N9 | Q9: =IFERROR(P9/O9,0) | R9: =TEXT(DATEVALUE(B9),"mmm") | S9: =TEXT(DATEVALUE(B9),"yyyy-mm")
A10: O001029 | B10: 2025-01-01 | C10: C0494 | D10: P0013 | E10: Storage Organizer | F10: Home & Kitchen | G10: North | H10: Delhi | I10: New Delhi | J10: Online | K10: 2 | L10: 596.1 | M10: 0.05 | N10: 712.43 | O10: =K10*L10*(1-M10) | P10: =O10-N10 | Q10: =IFERROR(P10/O10,0) | R10: =TEXT(DATEVALUE(B10),"mmm") | S10: =TEXT(DATEVALUE(B10),"yyyy-mm")
A11: O000992 | B11: 2025-01-01 | C11: C0568 | D11: P0021 | E11: Wallet | F11: Fashion | G11: West | H11: Gujarat | I11: Ahmedabad | J11: Online | K11: 2 | L11: 2034.07 | M11: 0 | N11: 2421.92 | O11: =K11*L11*(1-M11) | P11: =O11-N11 | Q11: =IFERROR(P11/O11,0) | R11: =TEXT(DATEVALUE(B11),"mmm") | S11: =TEXT(DATEVALUE(B11),"yyyy-mm")
A12: O000849 | B12: 2025-01-01 | C12: C0445 | D12: P0022 | E12: Face Wash | F12: Beauty | G12: South | H12: Telangana | I12: Hyderabad | J12: Online | K12: 5 | L12: 550.18 | M12: 0 | N12: 1728.13 | O12: =K12*L12*(1-M12) | P12: =O12-N12 | Q12: =IFERROR(P12/O12,0) | R12: =TEXT(DATEVALUE(B12),"mmm") | S12: =TEXT(DATEVALUE(B12),"yyyy-mm")
A13: O000756 | B13: 2025-01-01 | C13: C0051 | D13: P0016 | E13: Casual Shirt | F13: Fashion | G13: West | H13: Goa | I13: Margao | J13: Store | K13: 2 | L13: 1339.45 | M13: 0.05 | N13: 1841.15 | O13: =K13*L13*(1-M13) | P13: =O13-N13 | Q13: =IFERROR(P13/O13,0) | R13: =TEXT(DATEVALUE(B13),"mmm") | S13: =TEXT(DATEVALUE(B13),"yyyy-mm")
... A4996: O004826 | B4996: 2025-12-31 | C4996: C0001 | D4996: P0010 | E4996: Mixer Grinder | F4996: Home & Kitchen | G4996: South | H4996: Kerala | I4996: Thiruvananthapuram | J4996: Store | K4996: 1 | L4996: 1679.48 | M4996: 0.05 | N4996: 1063.61 | O4996: =K4996*L4996*(1-M4996) | P4996: =O4996-N4996 | Q4996: =IFERROR(P4996/O4996,0) | R4996: =TEXT(DATEVALUE(B4996),"mmm") | S4996: =TEXT(DATEVALUE(B4996),"yyyy-mm")

Sheet KPI_Summary
A1: RETAILPULSE BI - KEY PERFORMANCE INDICATORS (KPI SUMMARY)
A3: KPI Metric Name | B3: Calculated Value | C3: Excel Formula Reference | D3: Business Description
A4: Total Revenue | B4: =SUM(Orders!O2:O4996) | C4: =SUM(Orders!O2:O4996) | D4: Total sales revenue generated after discounts across all orders.
A5: Total Profit | B5: =SUM(Orders!P2:P4996) | C5: =SUM(Orders!P2:P4996) | D5: Total net profit earned (Revenue minus Product Costs).
A6: Total Orders | B6: =COUNTA(Orders!A2:A4996) | C6: =COUNTA(Orders!A2:A4996) | D6: Total number of valid order transactions processed.
A7: Total Units Sold | B7: =SUM(Orders!K2:K4996) | C7: =SUM(Orders!K2:K4996) | D7: Total quantity of physical items purchased across all orders.
A8: Average Order Value (AOV) | B8: =B4/B6 | C8: =B4/B6 | D8: Average revenue generated per order transaction.
A9: Overall Profit Margin | B9: =B5/B4 | C9: =B5/B4 | D9: Overall business profit margin percentage (Total Profit / Total Revenue).

Sheet Product_Analysis
A1: PRODUCT PERFORMANCE ANALYSIS (TOP 10 BY REVENUE & PROFIT)
A3: Top 10 Products by Revenue
A4: Product ID | B4: Product Name | C4: Category | D4: Revenue | E4: Profit | F4: Units Sold | G4: Margin %
A5: P0006 | B5: Mechanical Keyboard | C5: Electronics | D5: =SUMIF(Orders!D$2:D$4996, A5, Orders!O$2:O$4996) | E5: =SUMIF(Orders!D$2:D$4996, A5, Orders!P$2:P$4996) | F5: =SUMIF(Orders!D$2:D$4996, A5, Orders!K$2:K$4996) | G5: =E5/D5
A6: P0021 | B6: Wallet | C6: Fashion | D6: =SUMIF(Orders!D$2:D$4996, A6, Orders!O$2:O$4996) | E6: =SUMIF(Orders!D$2:D$4996, A6, Orders!P$2:P$4996) | F6: =SUMIF(Orders!D$2:D$4996, A6, Orders!K$2:K$4996) | G6: =E6/D6
A7: P0007 | B7: Wireless Mouse | C7: Electronics | D7: =SUMIF(Orders!D$2:D$4996, A7, Orders!O$2:O$4996) | E7: =SUMIF(Orders!D$2:D$4996, A7, Orders!P$2:P$4996) | F7: =SUMIF(Orders!D$2:D$4996, A7, Orders!K$2:K$4996) | G7: =E7/D7
A8: P0004 | B8: USB-C Hub | C8: Electronics | D8: =SUMIF(Orders!D$2:D$4996, A8, Orders!O$2:O$4996) | E8: =SUMIF(Orders!D$2:D$4996, A8, Orders!P$2:P$4996) | F8: =SUMIF(Orders!D$2:D$4996, A8, Orders!K$2:K$4996) | G8: =E8/D8
A9: P0016 | B9: Casual Shirt | C9: Fashion | D9: =SUMIF(Orders!D$2:D$4996, A9, Orders!O$2:O$4996) | E9: =SUMIF(Orders!D$2:D$4996, A9, Orders!P$2:P$4996) | F9: =SUMIF(Orders!D$2:D$4996, A9, Orders!K$2:K$4996) | G9: =E9/D9
A10: P0017 | B10: Jeans | C10: Fashion | D10: =SUMIF(Orders!D$2:D$4996, A10, Orders!O$2:O$4996) | E10: =SUMIF(Orders!D$2:D$4996, A10, Orders!P$2:P$4996) | F10: =SUMIF(Orders!D$2:D$4996, A10, Orders!K$2:K$4996) | G10: =E10/D10
A11: P0031 | B11: Cricket Bat | C11: Sports | D11: =SUMIF(Orders!D$2:D$4996, A11, Orders!O$2:O$4996) | E11: =SUMIF(Orders!D$2:D$4996, A11, Orders!P$2:P$4996) | F11: =SUMIF(Orders!D$2:D$4996, A11, Orders!K$2:K$4996) | G11: =E11/D11
A12: P0018 | B12: Backpack | C12: Fashion | D12: =SUMIF(Orders!D$2:D$4996, A12, Orders!O$2:O$4996) | E12: =SUMIF(Orders!D$2:D$4996, A12, Orders!P$2:P$4996) | F12: =SUMIF(Orders!D$2:D$4996, A12, Orders!K$2:K$4996) | G12: =E12/D12
A13: P0003 | B13: Smartwatch | C13: Electronics | D13: =SUMIF(Orders!D$2:D$4996, A13, Orders!O$2:O$4996) | E13: =SUMIF(Orders!D$2:D$4996, A13, Orders!P$2:P$4996) | F13: =SUMIF(Orders!D$2:D$4996, A13, Orders!K$2:K$4996) | G13: =E13/D13
A14: P0011 | B14: Cookware Set | C14: Home & Kitchen | D14: =SUMIF(Orders!D$2:D$4996, A14, Orders!O$2:O$4996) | E14: =SUMIF(Orders!D$2:D$4996, A14, Orders!P$2:P$4996) | F14: =SUMIF(Orders!D$2:D$4996, A14, Orders!K$2:K$4996) | G14: =E14/D14
A17: Top 10 Products by Profit
A18: Product ID | B18: Product Name | C18: Category | D18: Revenue | E18: Profit | F18: Units Sold | G18: Margin %
A19: P0006 | B19: Mechanical Keyboard | C19: Electronics | D19: =SUMIF(Orders!D$2:D$4996, A19, Orders!O$2:O$4996) | E19: =SUMIF(Orders!D$2:D$4996, A19, Orders!P$2:P$4996) | F19: =SUMIF(Orders!D$2:D$4996, A19, Orders!K$2:K$4996) | G19: =E19/D19
A20: P0021 | B20: Wallet | C20: Fashion | D20: =SUMIF(Orders!D$2:D$4996, A20, Orders!O$2:O$4996) | E20: =SUMIF(Orders!D$2:D$4996, A20, Orders!P$2:P$4996) | F20: =SUMIF(Orders!D$2:D$4996, A20, Orders!K$2:K$4996) | G20: =E20/D20
A21: P0003 | B21: Smartwatch | C21: Electronics | D21: =SUMIF(Orders!D$2:D$4996, A21, Orders!O$2:O$4996) | E21: =SUMIF(Orders!D$2:D$4996, A21, Orders!P$2:P$4996) | F21: =SUMIF(Orders!D$2:D$4996, A21, Orders!K$2:K$4996) | G21: =E21/D21
A22: P0007 | B22: Wireless Mouse | C22: Electronics | D22: =SUMIF(Orders!D$2:D$4996, A22, Orders!O$2:O$4996) | E22: =SUMIF(Orders!D$2:D$4996, A22, Orders!P$2:P$4996) | F22: =SUMIF(Orders!D$2:D$4996, A22, Orders!K$2:K$4996) | G22: =E22/D22
A23: P0009 | B23: Electric Kettle | C23: Home & Kitchen | D23: =SUMIF(Orders!D$2:D$4996, A23, Orders!O$2:O$4996) | E23: =SUMIF(Orders!D$2:D$4996, A23, Orders!P$2:P$4996) | F23: =SUMIF(Orders!D$2:D$4996, A23, Orders!K$2:K$4996) | G23: =E23/D23
A24: P0017 | B24: Jeans | C24: Fashion | D24: =SUMIF(Orders!D$2:D$4996, A24, Orders!O$2:O$4996) | E24: =SUMIF(Orders!D$2:D$4996, A24, Orders!P$2:P$4996) | F24: =SUMIF(Orders!D$2:D$4996, A24, Orders!K$2:K$4996) | G24: =E24/D24
A25: P0029 | B25: Yoga Mat | C25: Sports | D25: =SUMIF(Orders!D$2:D$4996, A25, Orders!O$2:O$4996) | E25: =SUMIF(Orders!D$2:D$4996, A25, Orders!P$2:P$4996) | F25: =SUMIF(Orders!D$2:D$4996, A25, Orders!K$2:K$4996) | G25: =E25/D25
A26: P0004 | B26: USB-C Hub | C26: Electronics | D26: =SUMIF(Orders!D$2:D$4996, A26, Orders!O$2:O$4996) | E26: =SUMIF(Orders!D$2:D$4996, A26, Orders!P$2:P$4996) | F26: =SUMIF(Orders!D$2:D$4996, A26, Orders!K$2:K$4996) | G26: =E26/D26
A27: P0016 | B27: Casual Shirt | C27: Fashion | D27: =SUMIF(Orders!D$2:D$4996, A27, Orders!O$2:O$4996) | E27: =SUMIF(Orders!D$2:D$4996, A27, Orders!P$2:P$4996) | F27: =SUMIF(Orders!D$2:D$4996, A27, Orders!K$2:K$4996) | G27: =E27/D27
A28: P0031 | B28: Cricket Bat | C28: Sports | D28: =SUMIF(Orders!D$2:D$4996, A28, Orders!O$2:O$4996) | E28: =SUMIF(Orders!D$2:D$4996, A28, Orders!P$2:P$4996) | F28: =SUMIF(Orders!D$2:D$4996, A28, Orders!K$2:K$4996) | G28: =E28/D28

Sheet Category_Analysis
A1: CATEGORY PERFORMANCE ANALYSIS (REVENUE & PROFIT)
A3: Category | B3: Revenue | C3: Profit | D3: Profit Margin | E3: Orders Count | F3: Units Sold
A4: Electronics | B4: =SUMIF(Orders!F$2:F$4996, A4, Orders!O$2:O$4996) | C4: =SUMIF(Orders!F$2:F$4996, A4, Orders!P$2:P$4996) | D4: =C4/B4 | E4: =COUNTIF(Orders!F$2:F$4996, A4) | F4: =SUMIF(Orders!F$2:F$4996, A4, Orders!K$2:K$4996)
A5: Fashion | B5: =SUMIF(Orders!F$2:F$4996, A5, Orders!O$2:O$4996) | C5: =SUMIF(Orders!F$2:F$4996, A5, Orders!P$2:P$4996) | D5: =C5/B5 | E5: =COUNTIF(Orders!F$2:F$4996, A5) | F5: =SUMIF(Orders!F$2:F$4996, A5, Orders!K$2:K$4996)
A6: Home & Kitchen | B6: =SUMIF(Orders!F$2:F$4996, A6, Orders!O$2:O$4996) | C6: =SUMIF(Orders!F$2:F$4996, A6, Orders!P$2:P$4996) | D6: =C6/B6 | E6: =COUNTIF(Orders!F$2:F$4996, A6) | F6: =SUMIF(Orders!F$2:F$4996, A6, Orders!K$2:K$4996)
A7: Sports | B7: =SUMIF(Orders!F$2:F$4996, A7, Orders!O$2:O$4996) | C7: =SUMIF(Orders!F$2:F$4996, A7, Orders!P$2:P$4996) | D7: =C7/B7 | E7: =COUNTIF(Orders!F$2:F$4996, A7) | F7: =SUMIF(Orders!F$2:F$4996, A7, Orders!K$2:K$4996)
A8: Beauty | B8: =SUMIF(Orders!F$2:F$4996, A8, Orders!O$2:O$4996) | C8: =SUMIF(Orders!F$2:F$4996, A8, Orders!P$2:P$4996) | D8: =C8/B8 | E8: =COUNTIF(Orders!F$2:F$4996, A8) | F8: =SUMIF(Orders!F$2:F$4996, A8, Orders!K$2:K$4996)
A9: Total / Overall | B9: =SUM(B4:B8) | C9: =SUM(C4:C8) | D9: =C9/B9 | E9: =SUM(E4:E8) | F9: =SUM(F4:F8)

Sheet Regional_Analysis
A1: REGIONAL PERFORMANCE ANALYSIS (REVENUE & PROFIT BY REGION)
A3: Region | B3: Revenue | C3: Profit | D3: Profit Margin | E3: Orders Count | F3: Units Sold
A4: West | B4: =SUMIF(Orders!G$2:G$4996, A4, Orders!O$2:O$4996) | C4: =SUMIF(Orders!G$2:G$4996, A4, Orders!P$2:P$4996) | D4: =C4/B4 | E4: =COUNTIF(Orders!G$2:G$4996, A4) | F4: =SUMIF(Orders!G$2:G$4996, A4, Orders!K$2:K$4996)
A5: South | B5: =SUMIF(Orders!G$2:G$4996, A5, Orders!O$2:O$4996) | C5: =SUMIF(Orders!G$2:G$4996, A5, Orders!P$2:P$4996) | D5: =C5/B5 | E5: =COUNTIF(Orders!G$2:G$4996, A5) | F5: =SUMIF(Orders!G$2:G$4996, A5, Orders!K$2:K$4996)
A6: North | B6: =SUMIF(Orders!G$2:G$4996, A6, Orders!O$2:O$4996) | C6: =SUMIF(Orders!G$2:G$4996, A6, Orders!P$2:P$4996) | D6: =C6/B6 | E6: =COUNTIF(Orders!G$2:G$4996, A6) | F6: =SUMIF(Orders!G$2:G$4996, A6, Orders!K$2:K$4996)
A7: East | B7: =SUMIF(Orders!G$2:G$4996, A7, Orders!O$2:O$4996) | C7: =SUMIF(Orders!G$2:G$4996, A7, Orders!P$2:P$4996) | D7: =C7/B7 | E7: =COUNTIF(Orders!G$2:G$4996, A7) | F7: =SUMIF(Orders!G$2:G$4996, A7, Orders!K$2:K$4996)
A8: Total / Overall | B8: =SUM(B4:B7) | C8: =SUM(C4:C7) | D8: =C8/B8 | E8: =SUM(E4:E7) | F8: =SUM(F4:F7)

Sheet Monthly_Analysis
A1: MONTHLY PERFORMANCE TREND ANALYSIS (REVENUE & PROFIT BY MONTH)
A3: Year-Month | B3: Revenue | C3: Profit | D3: Profit Margin | E3: Orders Count
A4: 2025-01 | B4: =SUMIF(Orders!S$2:S$4996, A4, Orders!O$2:O$4996) | C4: =SUMIF(Orders!S$2:S$4996, A4, Orders!P$2:P$4996) | D4: =C4/B4 | E4: =COUNTIF(Orders!S$2:S$4996, A4)
A5: 2025-02 | B5: =SUMIF(Orders!S$2:S$4996, A5, Orders!O$2:O$4996) | C5: =SUMIF(Orders!S$2:S$4996, A5, Orders!P$2:P$4996) | D5: =C5/B5 | E5: =COUNTIF(Orders!S$2:S$4996, A5)
A6: 2025-03 | B6: =SUMIF(Orders!S$2:S$4996, A6, Orders!O$2:O$4996) | C6: =SUMIF(Orders!S$2:S$4996, A6, Orders!P$2:P$4996) | D6: =C6/B6 | E6: =COUNTIF(Orders!S$2:S$4996, A6)
A7: 2025-04 | B7: =SUMIF(Orders!S$2:S$4996, A7, Orders!O$2:O$4996) | C7: =SUMIF(Orders!S$2:S$4996, A7, Orders!P$2:P$4996) | D7: =C7/B7 | E7: =COUNTIF(Orders!S$2:S$4996, A7)
A8: 2025-05 | B8: =SUMIF(Orders!S$2:S$4996, A8, Orders!O$2:O$4996) | C8: =SUMIF(Orders!S$2:S$4996, A8, Orders!P$2:P$4996) | D8: =C8/B8 | E8: =COUNTIF(Orders!S$2:S$4996, A8)
A9: 2025-06 | B9: =SUMIF(Orders!S$2:S$4996, A9, Orders!O$2:O$4996) | C9: =SUMIF(Orders!S$2:S$4996, A9, Orders!P$2:P$4996) | D9: =C9/B9 | E9: =COUNTIF(Orders!S$2:S$4996, A9)
A10: 2025-07 | B10: =SUMIF(Orders!S$2:S$4996, A10, Orders!O$2:O$4996) | C10: =SUMIF(Orders!S$2:S$4996, A10, Orders!P$2:P$4996) | D10: =C10/B10 | E10: =COUNTIF(Orders!S$2:S$4996, A10)
A11: 2025-08 | B11: =SUMIF(Orders!S$2:S$4996, A11, Orders!O$2:O$4996) | C11: =SUMIF(Orders!S$2:S$4996, A11, Orders!P$2:P$4996) | D11: =C11/B11 | E11: =COUNTIF(Orders!S$2:S$4996, A11)
A12: 2025-09 | B12: =SUMIF(Orders!S$2:S$4996, A12, Orders!O$2:O$4996) | C12: =SUMIF(Orders!S$2:S$4996, A12, Orders!P$2:P$4996) | D12: =C12/B12 | E12: =COUNTIF(Orders!S$2:S$4996, A12)
A13: 2025-10 | B13: =SUMIF(Orders!S$2:S$4996, A13, Orders!O$2:O$4996) | C13: =SUMIF(Orders!S$2:S$4996, A13, Orders!P$2:P$4996) | D13: =C13/B13 | E13: =COUNTIF(Orders!S$2:S$4996, A13)
A14: 2025-11 | B14: =SUMIF(Orders!S$2:S$4996, A14, Orders!O$2:O$4996) | C14: =SUMIF(Orders!S$2:S$4996, A14, Orders!P$2:P$4996) | D14: =C14/B14 | E14: =COUNTIF(Orders!S$2:S$4996, A14)
A15: 2025-12 | B15: =SUMIF(Orders!S$2:S$4996, A15, Orders!O$2:O$4996) | C15: =SUMIF(Orders!S$2:S$4996, A15, Orders!P$2:P$4996) | D15: =C15/B15 | E15: =COUNTIF(Orders!S$2:S$4996, A15)
A16: Total / Overall | B16: =SUM(B4:B15) | C16: =SUM(C4:C15) | D16: =C16/B16 | E16: =SUM(E4:E15)

Sheet Data_Audit
A1: RETAILPULSE BI - DATA AUDIT & QUALITY REPORT
A3: Data Quality Check | B3: Records Affected | C3: Severity / Type | D3: Action Taken & Resolution Details
A4: Duplicate Orders | B4: 5 | C4: Medium | D4: Identified duplicate Order_IDs (O004545, O000758, O003407, O003625, O003236). Removed 5 duplicate rows to prevent double-counting revenue.
A5: Missing Order Dates | B5: 5 | C5: High | D5: Found 5 rows at end of Orders sheet missing Order_Date (O000212, O002589, O003173, O003890, O004865). Removed rows as date is required for temporal analysis.
A6: Missing Product IDs | B6: 5 | C6: Medium | D6: Found 5 order rows with Product_Name but missing Product_ID. Populated Product_IDs via lookup from Products sheet (P0007, P0017, P0021, P0015, P0027).
A7: Missing Regions | B7: 10 | C7: Medium | D7: Found 10 order rows with missing Region. Resolved missing Region values via State/City mapping from Geography sheet (West, East, North).
A8: Invalid Quantity (<=0) | B8: 5 | C8: Low | D8: Found 5 orders with Quantity = -1. Corrected negative values to +1 (data entry typo correction).
A9: Invalid Discount (>100%) | B9: 5 | C9: Medium | D9: Found 5 orders with Discount = 1.5 (150%). Corrected to 0.15 (15%) based on standard discount scale.
A10: Total Issues Audited | B10: 35 | C10: Summary | D10: Total dataset size reduced from 5,005 raw rows to 4,995 100% clean, production-ready rows for BI modeling.

Sheet Business_Q&A
A1: RETAILPULSE BI - BUSINESS QUESTIONS & EXECUTIVE FINDINGS
A3: Q# | B3: Business Question | C3: Data-Backed Answer & Key Insight
A4: Q1 | B4: Which category generates the most revenue? | C4: Electronics is the top revenue generator at $3,696,120.55 (29.37% of total company revenue), followed by Fashion at $3,139,888.99.
A5: Q2 | B5: Which category generates the most profit? | C5: Electronics is also the most profitable category at $1,278,198.32, contributing 33.95% of total company profits.
A6: Q3 | B6: Is the highest-revenue category also the most profitable? | C6: Yes. Electronics leads both revenue ($3.70M) and profit ($1.28M) while maintaining the highest profit margin among all categories at 34.58%.
A7: Q4 | B7: Which region needs attention? | C7: East region needs strategic attention. It generates the lowest revenue ($1,900,923.74, only 15.1% share) and lowest order volume (758 orders), despite maintaining a healthy 30.24% margin.
A8: Q5 | B8: Which products generate strong sales but weak profitability? | C8: USB-C Hub ($688,009.15 revenue, 20.65% margin), Casual Shirt ($602,331.25 revenue, 22.73% margin), and Backpack ($541,522.25 revenue, 18.78% margin) suffer from margin leakage due to high discounting.
A9: Q6 | B9: Which month had the highest revenue? | C9: June 2025 recorded the highest monthly revenue at $1,192,417.47, closely followed by May 2025 ($1,143,317.55).
A10: Q7 | B10: Which month had the highest profit? | C10: June 2025 recorded the highest monthly profit at $350,167.99 (29.37% margin).
A11: Q8 | B11: Which sales channel performs better? | C11: Online channel dominates performance, generating $7,764,832.69 (61.7% of total revenue and 3,070 orders) vs. Store channel ($4,819,734.61, 1,925 orders). Both channels maintain similar ~30% profit margins.
A12: Q9 | B12: Who are the top 10 customers? | C12: Top 3 customers by revenue: C0568 ($208,136.93, 94 orders), C0694 ($205,307.75, 83 orders), and C0456 ($140,644.62, 65 orders).
A13: Q10 | B13: What are three actionable recommendations for management? | C13: 1. DISCONTINUE/RESTRICT EXCESSIVE DISCOUNTS ON LOW-MARGIN HIGH-VOLUME ITEMS: Cap discounts on USB-C Hubs, Backpacks, and Sneakers to boost margin from ~18-20% up to 28%+. 2. EXPAND REGIONAL DISTRIBUTION & MARKETING IN EAST REGION: Increase marketing and retail coverage in East region to elevate its 15.1% revenue contribution toward the 25% regional benchmark. 3. CAPITALIZE ON HIGH-MARGIN ELECTRONICS CROSS-SELLING: Bundle high-margin products (Mechanical Keyboards at 41% margin, Smartwatches at 44% margin) with high-volume purchases to maximize overall basket profitability.

Sheet Customers
A1: Customer_ID | B1: State | C1: City | D1: Region
A2: C0001 | B2: Karnataka | C2: Mysuru | D2: South
A3: C0001 | B3: Goa | C3: Panaji | D3: West
A4: C0001 | B4: Maharashtra | C4: Nagpur | D4: West
A5: C0001 | B5: Maharashtra | C5: Thane | D5: West
A6: C0001 | B6: Karnataka | C6: Bengaluru | D6: South
A7: C0001 | B7: Kerala | C7: Thiruvananthapuram | D7: South
A8: C0001 | B8: Uttar Pradesh | C8: Noida | D8: North
A9: C0001 | B9: Delhi | C9: New Delhi | D9: North
A10: C0002 | B10: West Bengal | C10: Durgapur | D10: East
A11: C0002 | B11: Bihar | C11: Gaya | D11: East
A12: C0003 | B12: West Bengal | C12: Durgapur | D12: East
... A68: C0013 | B68: Tamil Nadu | C68: Chennai | D68: South
A69: C0013 | B69: West Bengal | C69: Kolkata
A70: C0013 | B70: Karnataka | C70: Bengaluru | D70: South
A71: C0013 | B71: Karnataka | C71: Mangaluru | D71: South
A72: C0013 | B72: Punjab | C72: Ludhiana | D72: North
A73: C0013 | B73: Tamil Nadu | C73: Coimbatore | D73: South
A74: C0013 | B74: Punjab | C74: Jalandhar | D74: North
A75: C0014 | B75: Tamil Nadu | C75: Madurai | D75: South
A76: C0014 | B76: Gujarat | C76: Ahmedabad | D76: West
A77: C0014 | B77: Delhi | C77: New Delhi | D77: North
A78: C0014 | B78: Telangana | C78: Hyderabad | D78: South
A79: C0014 | B79: Bihar | C79: Patna | D79: East
A80: C0014 | B80: Uttar Pradesh | C80: Noida | D80: North
A81: C0014 | B81: Telangana | C81: Warangal | D81: South
... A820: C0179 | B820: Maharashtra | C820: Nagpur | D820: West
A821: C0179 | B821: Delhi | C821: New Delhi
A822: C0179 | B822: Bihar | C822: Gaya | D822: East
A823: C0179 | B823: Odisha | C823: Cuttack | D823: East
A824: C0179 | B824: Kerala | C824: Kochi | D824: South
A825: C0179 | B825: Goa | C825: Panaji | D825: West
A826: C0179 | B826: Punjab | C826: Ludhiana | D826: North
A827: C0179 | B827: Goa | C827: Margao | D827: West
A828: C0180 | B828: Karnataka | C828: Bengaluru | D828: South
A829: C0180 | B829: Delhi | C829: New Delhi | D829: North
A830: C0181 | B830: Gujarat | C830: Surat | D830: West
A831: C0181 | B831: Karnataka | C831: Mangaluru | D831: South
A832: C0181 | B832: Gujarat | C832: Ahmedabad | D832: West
A833: C0181 | B833: Odisha | C833: Bhubaneswar | D833: East
...

Sheet Products
A1: Product_ID | B1: Product_Name | C1: Category
A2: P0001 | B2: Wireless Headphones | C2: Electronics
A3: P0002 | B3: Bluetooth Speaker | C3: Electronics
A4: P0003 | B4: Smartwatch | C4: Electronics
A5: P0004 | B5: USB-C Hub | C5: Electronics
A6: P0005 | B6: Power Bank | C6: Electronics
A7: P0006 | B7: Mechanical Keyboard | C7: Electronics
A8: P0007 | B8: Wireless Mouse | C8: Electronics
A9: P0008 | B9: Air Fryer | C9: Home & Kitchen
A10: P0009 | B10: Electric Kettle | C10: Home & Kitchen
A11: P0010 | B11: Mixer Grinder | C11: Home & Kitchen
A12: P0011 | B12: Cookware Set | C12: Home & Kitchen
... A36: P0035 | B36: Skipping Rope | C36: Sports

Sheet Calendar
A1: Date | B1: Year | C1: Month_Number | D1: Month | E1: Year-Month | F1: Quarter
A2: 2025-01-01 | B2: 2025 | C2: 1 | D2: Jan | E2: 2025-01 | F2: Q1
A3: 2025-01-02 | B3: 2025 | C3: 1 | D3: Jan | E3: 2025-01 | F3: Q1
A4: 2025-01-03 | B4: 2025 | C4: 1 | D4: Jan | E4: 2025-01 | F4: Q1
A5: 2025-01-04 | B5: 2025 | C5: 1 | D5: Jan | E5: 2025-01 | F5: Q1
A6: 2025-01-05 | B6: 2025 | C6: 1 | D6: Jan | E6: 2025-01 | F6: Q1
A7: 2025-01-06 | B7: 2025 | C7: 1 | D7: Jan | E7: 2025-01 | F7: Q1
A8: 2025-01-07 | B8: 2025 | C8: 1 | D8: Jan | E8: 2025-01 | F8: Q1
A9: 2025-01-08 | B9: 2025 | C9: 1 | D9: Jan | E9: 2025-01 | F9: Q1
A10: 2025-01-09 | B10: 2025 | C10: 1 | D10: Jan | E10: 2025-01 | F10: Q1
A11: 2025-01-10 | B11: 2025 | C11: 1 | D11: Jan | E11: 2025-01 | F11: Q1
A12: 2025-01-11 | B12: 2025 | C12: 1 | D12: Jan | E12: 2025-01 | F12: Q1
A13: 2025-01-12 | B13: 2025 | C13: 1 | D13: Jan | E13: 2025-01 | F13: Q1
... A366: 2025-12-31 | B366: 2025 | C366: 12 | D366: Dec | E366: 2025-12 | F366: Q4

Sheet Geography
A1: Region | B1: State | C1: City
A2: East | B2: Bihar | C2: Gaya
A3: East | B3: Bihar | C3: Patna
A4: East | B4: Odisha | C4: Bhubaneswar
A5: East | B5: Odisha | C5: Cuttack
A6: East | B6: West Bengal | C6: Durgapur
A7: East | B7: West Bengal | C7: Kolkata
A8: North | B8: Delhi | C8: New Delhi
A9: North | B9: Haryana | C9: Faridabad
A10: North | B10: Haryana | C10: Gurugram
A11: North | B11: Punjab | C11: Amritsar
A12: North | B12: Punjab | C12: Jalandhar
... A37: West | B37: Maharashtra | C37: Thane
B38: Bihar | C38: Gaya
B39: Delhi | C39: New Delhi
B40: Gujarat | C40: Surat
B41: Gujarat | C41: Vadodara
B42: Punjab | C42: Ludhiana
B43: Uttar Pradesh | C43: Kanpur
B44: Uttar Pradesh | C44: Noida
B45: West Bengal | C45: Kolkata
